<mujoco model="pioneer">
    <compiler angle="radian"/>
    <size njmax="500" nconmax="100"/>

    <!-- we don't need no gravity: this is a purely kinematic environment -->
    <option gravity="0 0 0"/>

    <worldbody>
        <light mode="fixed" directional="true" pos="0 0 10" dir="0 0 -1" ambient="0.1 0.1 0.1"/>

        <body name="ground" pos="0 0 0">
            <geom pos="0 0 0" rgba="0.4 0.4 0.4 1" size="6 6 1" type="plane"/>
        </body>

        <!-- everything related to the robot itself must have the 'robot:' prefix -->
        <body name="robot:base" pos="0 0 0">
            <geom size="1 0.25" pos="0 0 0.25" rgba="0.175 0.175 0.175 1" type="cylinder"/>

            <body name="robot:rotator" pos="0 0 0.25">
                <joint name="robot:base_to_rotator" pos="0 0 0" axis="0 0 1" limited="true" range="-1.309 1.309" type="hinge"/>
                <geom size="0.25 0.75 0.25" pos="0 0 0.5" rgba="1 0.5 0.05 1" type="box"/>
                <geom size="0.25 0.25 1.0" pos="0 -0.5 1.75" rgba="1 0.5 0.05 1" type="box"/>
                <geom size="0.25 0.25 1.0" pos="0 0.5 1.75" rgba="1 0.5 0.05 1" type="box"/>

                <body name="robot:arm1" pos="0 0 2.0" euler="0 -0.7854 0">
                    <joint name="robot:rotator_to_arm1" pos="0 0 0" axis="0 1 0" limited="true" range="-0.7854 0.7854" type="hinge"/>
                    <geom size="1.5 0.25 0.25" pos="0.75 0 0.25" rgba="0 0 1 1" type="box"/>

                    <body name="robot:arm2" pos="2 0 0" euler="0 0 0">
                        <joint name="robot:arm1_to_arm2" pos="0 0 0.25" axis="0 1 0" limited="true" range="-1.5708 1.5708" type="hinge"/>
                        <geom size="1.5 0.25 0.25" pos="2 0 0.25" rgba="0 0.5 0 1" type="box"/>

                        <body name="robot:arm3" pos="3.25 0 0" euler="0 0 0">
                            <joint name="robot:arm2_to_arm3" pos="0 0 0.25" axis="0 1 0" limited="true" range="-1.5708 1.5708" type="hinge"/>
                             <geom size="1.5 0.25 0.25" pos="2 0 0.25" rgba="0.3 0 0.5 1" type="box"/>

                            <body name="robot:pointer" pos="3.5 0 0">
                                <geom size="0.125" pos="0.125 0 0.25" rgba="0.9 0.2 0.2 1" type="sphere"/>
                            </body>
                        </body>

                    </body>
                </body>
            </body>
        </body>

        <!-- obstacles <body> position must always be 0: we only care about the autogenerated <geom> entries inside -->
        <body name="obstacles">
            <geom size="0.1 0.1 3" pos="4 -2 3" rgba="0.3 0.3 0.3 1" type="box"/>
        </body>

        <!-- target <geom> position must always be 0: target location is controlled by the enclosing <body> -->
        <body name="target" pos="5 0 1">
            <geom conaffinity="0" contype="0" size="0.125" rgba="0.1 0.9 0.1 0.5" type="sphere"/>
        </body>

    </worldbody>
</mujoco>
