<?xml version="1.0"?>
<robot name="pioneer">
    <material name="ground_mat">
        <color rgba="0.4 0.4 0.4 1"/>
    </material>

    <material name="rotator_mat">
        <color rgba="0.175 0.175 0.175 1"/>
    </material>

    <material name="hinge_mat">
        <color rgba="1 0.5 0.05 1"/>
    </material>

    <material name="arm_mat">
        <color rgba="0.07 0.25 0.54 1"/>
    </material>

    <material name="pointer_mat">
        <color rgba="0.1 0.9 0.1 1"/>
    </material>

    <material name="obstacle_mat">
        <color rgba="0.3 0.3 0.3 1"/>
    </material>

    <link name="world"/>

    <link name="robot:base">
        <inertial>
            <mass value="1.0"/>
           <inertia ixx="1.0" ixy="0.0" ixz="0.0" iyy="1.0" iyz="0.0" izz="1.0"/>
        </inertial>
    </link>

    <link name="robot:rotator1">
        <visual>
            <origin rpy="0 0 0" xyz="0 0 0.5"/>
            <geometry>
                <cylinder radius="4" length="1"/>
            </geometry>
            <material name="rotator_mat"/>
        </visual>
        <inertial>
            <mass value="1.0"/>
           <inertia ixx="1.0" ixy="0.0" ixz="0.0" iyy="1.0" iyz="0.0" izz="1.0"/>
        </inertial>
    </link>

    <link name="robot:hinge1">
        <visual>
            <origin rpy="0 0 0" xyz="0 0 1.5"/>
            <geometry>
                <box size="2 3 1"/>
            </geometry>
            <material name="hinge_mat"/>
        </visual>
        <visual>
            <origin rpy="0 0 0" xyz="0 -1 3"/>
            <geometry>
                <box size="2 1 2"/>
            </geometry>
            <material name="hinge_mat"/>
        </visual>
        <visual>
            <origin rpy="0 0 0" xyz="0 1 3"/>
            <geometry>
                <box size="2 1 2"/>
            </geometry>
            <material name="hinge_mat"/>
        </visual>
        <inertial>
            <mass value="1.0"/>
            <inertia ixx="1.0" ixy="0.0" ixz="0.0" iyy="1.0" iyz="0.0" izz="1.0"/>
        </inertial>
    </link>

    <link name="robot:arm1">
        <visual>
            <origin rpy="0 -1.5708 0" xyz="0 0 6"/>
            <geometry>
                <box size="12 1 2"/>
            </geometry>
            <material name="arm_mat"/>
        </visual>
        <inertial>
            <mass value="1.0"/>
            <inertia ixx="1.0" ixy="0.0" ixz="0.0" iyy="1.0" iyz="0.0" izz="1.0"/>
        </inertial>
    </link>

    <link name="robot:arm2">
        <visual>
            <origin rpy="0 3.1416 0" xyz="4 1 0"/>
            <geometry>
                <box size="10 1 2"/>
            </geometry>
            <material name="arm_mat"/>
        </visual>
        <inertial>
            <mass value="1.0"/>
            <inertia ixx="1.0" ixy="0.0" ixz="0.0" iyy="1.0" iyz="0.0" izz="1.0"/>
        </inertial>
    </link>

    <link name="robot:rotator2">
        <visual>
            <origin rpy="0 1.5708 0" xyz="9.2 0 0"/>
            <geometry>
                <cylinder radius="1" length="0.4"/>
            </geometry>
            <material name="rotator_mat"/>
        </visual>
        <inertial>
            <mass value="1.0"/>
           <inertia ixx="1.0" ixy="0.0" ixz="0.0" iyy="1.0" iyz="0.0" izz="1.0"/>
        </inertial>
    </link>

    <link name="robot:hinge2">
        <visual>
            <origin rpy="0 0 0" xyz="10.4 0 0"/>
            <geometry>
                <box size="2 0.5 1"/>
            </geometry>
            <material name="hinge_mat"/>
        </visual>
        <inertial>
            <mass value="1.0"/>
            <inertia ixx="1.0" ixy="0.0" ixz="0.0" iyy="1.0" iyz="0.0" izz="1.0"/>
        </inertial>
    </link>

    <link name="robot:arm3">
        <visual>
            <origin rpy="0 0 0" xyz="1 0.5 0"/>
            <geometry>
                <box size="3 0.5 1"/>
            </geometry>
            <material name="arm_mat"/>
        </visual>
         <visual>
            <origin rpy="0 0 0" xyz="1 -0.5 0"/>
            <geometry>
                <box size="3 0.5 1"/>
            </geometry>
            <material name="arm_mat"/>
        </visual>
        <inertial>
            <mass value="1.0"/>
            <inertia ixx="1.0" ixy="0.0" ixz="0.0" iyy="1.0" iyz="0.0" izz="1.0"/>
        </inertial>
    </link>

    <link name="robot:rotator3">
        <visual>
            <origin rpy="0 1.5708 0" xyz="2.6 0 0"/>
            <geometry>
                <cylinder radius="1" length="0.4"/>
            </geometry>
            <material name="rotator_mat"/>
        </visual>
        <inertial>
            <mass value="1.0"/>
           <inertia ixx="1.0" ixy="0.0" ixz="0.0" iyy="1.0" iyz="0.0" izz="1.0"/>
        </inertial>
    </link>

    <link name="robot:effector">
        <visual>
            <origin rpy="0 0 0" xyz="3.2 0 0"/>
            <geometry>
                <box size="1.0 0.2 0.2"/>
            </geometry>
            <material name="hinge_mat"/>
        </visual>
         <visual>
            <origin rpy="0 0 0" xyz="3.6 0 0.5"/>
            <geometry>
                <box size="0.2 0.2 2.5"/>
            </geometry>
            <material name="hinge_mat"/>
        </visual>
        <inertial>
            <mass value="1.0"/>
            <inertia ixx="1.0" ixy="0.0" ixz="0.0" iyy="1.0" iyz="0.0" izz="1.0"/>
        </inertial>
    </link>

    <link name="robot:pointer">
        <visual>
            <origin rpy="0 0 0" xyz="0 0 0"/>
            <geometry>
                <sphere radius="0.2"/>
            </geometry>
            <material name="pointer_mat"/>
        </visual>
        <inertial>
            <mass value="1.0"/>
            <inertia ixx="1.0" ixy="0.0" ixz="0.0" iyy="1.0" iyz="0.0" izz="1.0"/>
        </inertial>
    </link>

    <joint name="world_to_base" type="fixed">
        <parent link="world"/>
        <child link="robot:base"/>
    </joint>

    <joint name="robot:base_to_rotator1" type="revolute">
        <parent link="robot:base"/>
        <child link="robot:rotator1"/>
        <limit lower="-3.1416" upper="3.1416" effort="1.0"/>
        <axis xyz="0 0 1"/>
    </joint>

    <joint name="robot:rotator1_to_hinge1" type="fixed">
        <parent link="robot:rotator1"/>
        <child link="robot:hinge1"/>
    </joint>

    <joint name="robot:hinge1_to_arm1" type="revolute">
        <parent link="robot:hinge1"/>
        <child link="robot:arm1"/>
        <limit lower="-1.309" upper="1.309" effort="1.0"/>
        <origin xyz="0 0 3"/>
        <axis xyz="0 1 0"/>
    </joint>

    <joint name="robot:arm1_to_arm2" type="revolute">
        <parent link="robot:arm1"/>
        <child link="robot:arm2"/>
        <limit lower="-1.309" upper="1.309" effort="1.0"/>
        <origin xyz="0 0 11"/>
        <axis xyz="0 1 0"/>
    </joint>

    <joint name="robot:arm2_to_rotator2" type="revolute">
        <parent link="robot:arm2"/>
        <child link="robot:rotator2"/>
        <limit lower="-3.1416" upper="3.1416" effort="1.0"/>
        <origin xyz="0 1 0"/>
        <axis xyz="1 0 0"/>
    </joint>

    <joint name="robot:rotator2_to_hinge2" type="fixed">
        <parent link="robot:rotator2"/>
        <child link="robot:hinge2"/>
    </joint>

    <joint name="robot:hinge2_to_arm3" type="revolute">
        <parent link="robot:hinge2"/>
        <child link="robot:arm3"/>
        <limit lower="-1.5708" upper="1.5708" effort="1.0"/>
        <origin xyz="11 0 0"/>
        <axis xyz="0 1 0"/>
    </joint>

    <joint name="robot:arm3_to_rotator3" type="revolute">
        <parent link="robot:arm3"/>
        <child link="robot:rotator3"/>
        <limit lower="-3.1416" upper="3.1416" effort="1.0"/>
        <origin xyz="0 0 0"/>
        <axis xyz="1 0 0"/>
    </joint>

    <joint name="robot:rotator3_to_effector" type="fixed">
        <parent link="robot:rotator3"/>
        <child link="robot:effector"/>
    </joint>

    <joint name="robot:effector_to_pointer" type="fixed">
        <parent link="robot:effector"/>
        <child link="robot:pointer"/>
        <origin xyz="3.6 0 1.9"/>
    </joint>
</robot>
